test_0 (__main__.lab1a.test_0)
[Lab 1] - [Investigation 3] - [Part 2] - printing - Test for file creation: ./lab1a.py ... ok
test_a (__main__.lab1a.test_a)
[Lab 1] - [Investigation 3] - [Part 2] - printing - Test for errors running: ./lab1a.py ... /usr/lib/python3.12/subprocess.py:822: ResourceWarning: unclosed file <_io.TextIOWrapper name=3 encoding='UTF-8'>
  _cleanup()
ResourceWarning: Enable tracemalloc to get the object allocation traceback
FAIL

======================================================================
FAIL: test_a (__main__.lab1a.test_a)
[Lab 1] - [Investigation 3] - [Part 2] - printing - Test for errors running: ./lab1a.py
----------------------------------------------------------------------
Traceback (most recent call last):
  File "/home/sbashyal/ops445/lab1/./CheckLab1.py", line 71, in test_a
    self.assertEqual(return_code, 0, msg=error_output)
AssertionError: 2 != 0 : your program exited with a error(HINT: try running your program to see/read the error)

----------------------------------------------------------------------
Ran 2 tests in 0.008s

FAILED (failures=1)
OPS445 Lab Report - System Information for running ./CheckLab1.py
=================================================================
    User login name: sbashyal
    Git Email: Sbashyal@myseneca.ca
    Linux system name: President
    Python executable: /usr/bin/python3
    Python version:  3.12.3 (main, Feb  4 2025, 14:48:35) [GCC 13.3.0]
    OS Platform: linux
    Working Directory: /home/sbashyal/ops445/lab1
    Start at: Thu May  8 13:15:42 2025
=================================================================
